Workbook

Sheet Concentrado
A1: Año | B1: Entidad Federativa | C1: Consultorios | D1: Camas hospitalarias | E1: Camas no hospitalarias | F1: Quirófanos | G1: Salas expulsión
A2: 2024 | B2: Nacional | C2: 86304 | D2: 96988 | E2: 53160 | F2: 4495 | G2: 2025
A3: 2024 | B3: Aguascalientes | C3: 956 | D3: 1079 | E3: 672 | F3: 60 | G3: 15
A4: 2024 | B4: Baja California | C4: 1767 | D4: 2606 | E4: 1222 | F4: 109 | G4: 37
A5: 2024 | B5: Baja California Sur | C5: 714 | D5: 892 | E5: 509 | F5: 45 | G5: 24
A6: 2024 | B6: Campeche | C6: 834 | D6: 847 | E6: 598 | F6: 47 | G6: 23
A7: 2024 | B7: Coahuila | C7: 2120 | D7: 3075 | E7: 1252 | F7: 154 | G7: 55
A8: 2024 | B8: Colima | C8: 758 | D8: 701 | E8: 488 | F8: 36 | G8: 12
A9: 2024 | B9: Chiapas | C9: 3953 | D9: 2427 | E9: 1914 | F9: 152 | G9: 129
A10: 2024 | B10: Chihuahua | C10: 2343 | D10: 3223 | E10: 1612 | F10: 144 | G10: 70
A11: 2024 | B11: CDMX | C11: 9844 | D11: 15698 | E11: 6055 | F11: 696 | G11: 115
A12: 2024 | B12: Durango | C12: 1478 | D12: 1640 | E12: 879 | F12: 62 | G12: 45
A13: 2024 | B13: Guanajuato | C13: 3096 | D13: 3849 | E13: 2575 | F13: 186 | G13: 79
... A430: 2012 | B430: Zacatecas | C430: 1179 | D430: 1007 | E430: 851 | F430: 53 | G430: 85

Sheet NACIONAL
A1: Año | B1: Consultorios | C1: Camas hospitalarias | D1: Camas no hospitalarias | E1: Quirófanos | F1: Salas expulsión
A2: 2012 | B2: =SUMIFS(Concentrado!C$2:C430,Concentrado!$A$2:$A430,"="&$A2,Concentrado!$B$2:$B430, "=Nacional") -> 68429 | C2: =SUMIFS(Concentrado!D$2:D430,Concentrado!$A$2:$A430,"="&$A2,Concentrado!$B$2:$B430, "=Nacional") -> 85656 | D2: =SUMIFS(Concentrado!E$2:E430,Concentrado!$A$2:$A430,"="&$A2,Concentrado!$B$2:$B430, "=Nacional") -> 54439 | E2: =SUMIFS(Concentrado!F$2:F430,Concentrado!$A$2:$A430,"="&$A2,Concentrado!$B$2:$B430, "=Nacional") -> 3594 | F2: =SUMIFS(Concentrado!G$2:G430,Concentrado!$A$2:$A430,"="&$A2,Concentrado!$B$2:$B430, "=Nacional") -> 2058
A3: 2013 | B3: =SUMIFS(Concentrado!C$2:C431,Concentrado!$A$2:$A431,"="&$A3,Concentrado!$B$2:$B431, "=Nacional") -> 71916 | C3: =SUMIFS(Concentrado!D$2:D431,Concentrado!$A$2:$A431,"="&$A3,Concentrado!$B$2:$B431, "=Nacional") -> 87509 | D3: =SUMIFS(Concentrado!E$2:E431,Concentrado!$A$2:$A431,"="&$A3,Concentrado!$B$2:$B431, "=Nacional") -> 58940 | E3: =SUMIFS(Concentrado!F$2:F431,Concentrado!$A$2:$A431,"="&$A3,Concentrado!$B$2:$B431, "=Nacional") -> 3984 | F3: =SUMIFS(Concentrado!G$2:G431,Concentrado!$A$2:$A431,"="&$A3,Concentrado!$B$2:$B431, "=Nacional") -> 2171
A4: 2014 | B4: =SUMIFS(Concentrado!C$2:C432,Concentrado!$A$2:$A432,"="&$A4,Concentrado!$B$2:$B432, "=Nacional") -> 74579 | C4: =SUMIFS(Concentrado!D$2:D432,Concentrado!$A$2:$A432,"="&$A4,Concentrado!$B$2:$B432, "=Nacional") -> 89181 | D4: =SUMIFS(Concentrado!E$2:E432,Concentrado!$A$2:$A432,"="&$A4,Concentrado!$B$2:$B432, "=Nacional") -> 59871 | E4: =SUMIFS(Concentrado!F$2:F432,Concentrado!$A$2:$A432,"="&$A4,Concentrado!$B$2:$B432, "=Nacional") -> 4009 | F4: =SUMIFS(Concentrado!G$2:G432,Concentrado!$A$2:$A432,"="&$A4,Concentrado!$B$2:$B432, "=Nacional") -> 2141
A5: 2015 | B5: =SUMIFS(Concentrado!C$2:C433,Concentrado!$A$2:$A433,"="&$A5,Concentrado!$B$2:$B433, "=Nacional") -> 74462 | C5: =SUMIFS(Concentrado!D$2:D433,Concentrado!$A$2:$A433,"="&$A5,Concentrado!$B$2:$B433, "=Nacional") -> 87603 | D5: =SUMIFS(Concentrado!E$2:E433,Concentrado!$A$2:$A433,"="&$A5,Concentrado!$B$2:$B433, "=Nacional") -> 51914 | E5: =SUMIFS(Concentrado!F$2:F433,Concentrado!$A$2:$A433,"="&$A5,Concentrado!$B$2:$B433, "=Nacional") -> 4072 | F5: =SUMIFS(Concentrado!G$2:G433,Concentrado!$A$2:$A433,"="&$A5,Concentrado!$B$2:$B433, "=Nacional") -> 2153
A6: 2016 | B6: =SUMIFS(Concentrado!C$2:C434,Concentrado!$A$2:$A434,"="&$A6,Concentrado!$B$2:$B434, "=Nacional") -> 76416 | C6: =SUMIFS(Concentrado!D$2:D434,Concentrado!$A$2:$A434,"="&$A6,Concentrado!$B$2:$B434, "=Nacional") -> 89155 | D6: =SUMIFS(Concentrado!E$2:E434,Concentrado!$A$2:$A434,"="&$A6,Concentrado!$B$2:$B434, "=Nacional") -> 51721 | E6: =SUMIFS(Concentrado!F$2:F434,Concentrado!$A$2:$A434,"="&$A6,Concentrado!$B$2:$B434, "=Nacional") -> 4100 | F6: =SUMIFS(Concentrado!G$2:G434,Concentrado!$A$2:$A434,"="&$A6,Concentrado!$B$2:$B434, "=Nacional") -> 2235
A7: 2017 | B7: =SUMIFS(Concentrado!C$2:C435,Concentrado!$A$2:$A435,"="&$A7,Concentrado!$B$2:$B435, "=Nacional") -> 76201 | C7: =SUMIFS(Concentrado!D$2:D435,Concentrado!$A$2:$A435,"="&$A7,Concentrado!$B$2:$B435, "=Nacional") -> 89085 | D7: =SUMIFS(Concentrado!E$2:E435,Concentrado!$A$2:$A435,"="&$A7,Concentrado!$B$2:$B435, "=Nacional") -> 50130 | E7: =SUMIFS(Concentrado!F$2:F435,Concentrado!$A$2:$A435,"="&$A7,Concentrado!$B$2:$B435, "=Nacional") -> 4169 | F7: =SUMIFS(Concentrado!G$2:G435,Concentrado!$A$2:$A435,"="&$A7,Concentrado!$B$2:$B435, "=Nacional") -> 2130
A8: 2018 | B8: =SUMIFS(Concentrado!C$2:C436,Concentrado!$A$2:$A436,"="&$A8,Concentrado!$B$2:$B436, "=Nacional") -> 77563 | C8: =SUMIFS(Concentrado!D$2:D436,Concentrado!$A$2:$A436,"="&$A8,Concentrado!$B$2:$B436, "=Nacional") -> 89562 | D8: =SUMIFS(Concentrado!E$2:E436,Concentrado!$A$2:$A436,"="&$A8,Concentrado!$B$2:$B436, "=Nacional") -> 50019 | E8: =SUMIFS(Concentrado!F$2:F436,Concentrado!$A$2:$A436,"="&$A8,Concentrado!$B$2:$B436, "=Nacional") -> 4162 | F8: =SUMIFS(Concentrado!G$2:G436,Concentrado!$A$2:$A436,"="&$A8,Concentrado!$B$2:$B436, "=Nacional") -> 2003
A9: 2019 | B9: =SUMIFS(Concentrado!C$2:C437,Concentrado!$A$2:$A437,"="&$A9,Concentrado!$B$2:$B437, "=Nacional") -> 76875 | C9: =SUMIFS(Concentrado!D$2:D437,Concentrado!$A$2:$A437,"="&$A9,Concentrado!$B$2:$B437, "=Nacional") -> 89538 | D9: =SUMIFS(Concentrado!E$2:E437,Concentrado!$A$2:$A437,"="&$A9,Concentrado!$B$2:$B437, "=Nacional") -> 50466 | E9: =SUMIFS(Concentrado!F$2:F437,Concentrado!$A$2:$A437,"="&$A9,Concentrado!$B$2:$B437, "=Nacional") -> 4198 | F9: =SUMIFS(Concentrado!G$2:G437,Concentrado!$A$2:$A437,"="&$A9,Concentrado!$B$2:$B437, "=Nacional") -> 2221
A10: 2020 | B10: =SUMIFS(Concentrado!C$2:C438,Concentrado!$A$2:$A438,"="&$A10,Concentrado!$B$2:$B438, "=Nacional") -> 79067 | C10: =SUMIFS(Concentrado!D$2:D438,Concentrado!$A$2:$A438,"="&$A10,Concentrado!$B$2:$B438, "=Nacional") -> 93219 | D10: =SUMIFS(Concentrado!E$2:E438,Concentrado!$A$2:$A438,"="&$A10,Concentrado!$B$2:$B438, "=Nacional") -> 52342 | E10: =SUMIFS(Concentrado!F$2:F438,Concentrado!$A$2:$A438,"="&$A10,Concentrado!$B$2:$B438, "=Nacional") -> 4181 | F10: =SUMIFS(Concentrado!G$2:G438,Concentrado!$A$2:$A438,"="&$A10,Concentrado!$B$2:$B438, "=Nacional") -> 2179
A11: 2021 | B11: =SUMIFS(Concentrado!C$2:C439,Concentrado!$A$2:$A439,"="&$A11,Concentrado!$B$2:$B439, "=Nacional") -> 78870 | C11: =SUMIFS(Concentrado!D$2:D439,Concentrado!$A$2:$A439,"="&$A11,Concentrado!$B$2:$B439, "=Nacional") -> 94047 | D11: =SUMIFS(Concentrado!E$2:E439,Concentrado!$A$2:$A439,"="&$A11,Concentrado!$B$2:$B439, "=Nacional") -> 52047 | E11: =SUMIFS(Concentrado!F$2:F439,Concentrado!$A$2:$A439,"="&$A11,Concentrado!$B$2:$B439, "=Nacional") -> 4243 | F11: =SUMIFS(Concentrado!G$2:G439,Concentrado!$A$2:$A439,"="&$A11,Concentrado!$B$2:$B439, "=Nacional") -> 2063
A12: 2022 | B12: =SUMIFS(Concentrado!C$2:C440,Concentrado!$A$2:$A440,"="&$A12,Concentrado!$B$2:$B440, "=Nacional") -> 83750 | C12: =SUMIFS(Concentrado!D$2:D440,Concentrado!$A$2:$A440,"="&$A12,Concentrado!$B$2:$B440, "=Nacional") -> 95780 | D12: =SUMIFS(Concentrado!E$2:E440,Concentrado!$A$2:$A440,"="&$A12,Concentrado!$B$2:$B440, "=Nacional") -> 48900 | E12: =SUMIFS(Concentrado!F$2:F440,Concentrado!$A$2:$A440,"="&$A12,Concentrado!$B$2:$B440, "=Nacional") -> 4410 | F12: =SUMIFS(Concentrado!G$2:G440,Concentrado!$A$2:$A440,"="&$A12,Concentrado!$B$2:$B440, "=Nacional") -> 1970
A13: 2023 | B13: =SUMIFS(Concentrado!C$2:C441,Concentrado!$A$2:$A441,"="&$A13,Concentrado!$B$2:$B441, "=Nacional") -> 84929 | C13: =SUMIFS(Concentrado!D$2:D441,Concentrado!$A$2:$A441,"="&$A13,Concentrado!$B$2:$B441, "=Nacional") -> 95061 | D13: =SUMIFS(Concentrado!E$2:E441,Concentrado!$A$2:$A441,"="&$A13,Concentrado!$B$2:$B441, "=Nacional") -> 50438 | E13: =SUMIFS(Concentrado!F$2:F441,Concentrado!$A$2:$A441,"="&$A13,Concentrado!$B$2:$B441, "=Nacional") -> 4385 | F13: =SUMIFS(Concentrado!G$2:G441,Concentrado!$A$2:$A441,"="&$A13,Concentrado!$B$2:$B441, "=Nacional") -> 1984
A14: 2024 | B14: =SUMIFS(Concentrado!C$2:C442,Concentrado!$A$2:$A442,"="&$A14,Concentrado!$B$2:$B442, "=Nacional") -> 86304 | C14: =SUMIFS(Concentrado!D$2:D442,Concentrado!$A$2:$A442,"="&$A14,Concentrado!$B$2:$B442, "=Nacional") -> 96988 | D14: =SUMIFS(Concentrado!E$2:E442,Concentrado!$A$2:$A442,"="&$A14,Concentrado!$B$2:$B442, "=Nacional") -> 53160 | E14: =SUMIFS(Concentrado!F$2:F442,Concentrado!$A$2:$A442,"="&$A14,Concentrado!$B$2:$B442, "=Nacional") -> 4495 | F14: =SUMIFS(Concentrado!G$2:G442,Concentrado!$A$2:$A442,"="&$A14,Concentrado!$B$2:$B442, "=Nacional") -> 2025

Sheet AGS
A1: Año | B1: Consultorios | C1: Camas hospitalarias | D1: Camas no hospitalarias | E1: Quirófanos | F1: Salas expulsión
A2: 2012 | B2: =SUMIFS(Concentrado!C$2:C$430,Concentrado!$A$2:$A$430,"="&$A2,Concentrado!$B$2:$B$430, "=Aguascalientes") -> 808 | C2: =SUMIFS(Concentrado!D$2:D$430,Concentrado!$A$2:$A$430,"="&$A2,Concentrado!$B$2:$B$430, "=Aguascalientes") -> 878 | D2: =SUMIFS(Concentrado!E$2:E$430,Concentrado!$A$2:$A$430,"="&$A2,Concentrado!$B$2:$B$430, "=Aguascalientes") -> 526 | E2: =SUMIFS(Concentrado!F$2:F$430,Concentrado!$A$2:$A$430,"="&$A2,Concentrado!$B$2:$B$430, "=Aguascalientes") -> 36 | F2: =SUMIFS(Concentrado!G$2:G$430,Concentrado!$A$2:$A$430,"="&$A2,Concentrado!$B$2:$B$430, "=Aguascalientes") -> 15
A3: 2013 | B3: =SUMIFS(Concentrado!C$2:C$430,Concentrado!$A$2:$A$430,"="&$A3,Concentrado!$B$2:$B$430, "=Aguascalientes") -> 835 | C3: =SUMIFS(Concentrado!D$2:D$430,Concentrado!$A$2:$A$430,"="&$A3,Concentrado!$B$2:$B$430, "=Aguascalientes") -> 875 | D3: =SUMIFS(Concentrado!E$2:E$430,Concentrado!$A$2:$A$430,"="&$A3,Concentrado!$B$2:$B$430, "=Aguascalientes") -> 559 | E3: =SUMIFS(Concentrado!F$2:F$430,Concentrado!$A$2:$A$430,"="&$A3,Concentrado!$B$2:$B$430, "=Aguascalientes") -> 41 | F3: =SUMIFS(Concentrado!G$2:G$430,Concentrado!$A$2:$A$430,"="&$A3,Concentrado!$B$2:$B$430, "=Aguascalientes") -> 15
A4: 2014 | B4: =SUMIFS(Concentrado!C$2:C$430,Concentrado!$A$2:$A$430,"="&$A4,Concentrado!$B$2:$B$430, "=Aguascalientes") -> 899 | C4: =SUMIFS(Concentrado!D$2:D$430,Concentrado!$A$2:$A$430,"="&$A4,Concentrado!$B$2:$B$430, "=Aguascalientes") -> 874 | D4: =SUMIFS(Concentrado!E$2:E$430,Concentrado!$A$2:$A$430,"="&$A4,Concentrado!$B$2:$B$430, "=Aguascalientes") -> 506 | E4: =SUMIFS(Concentrado!F$2:F$430,Concentrado!$A$2:$A$430,"="&$A4,Concentrado!$B$2:$B$430, "=Aguascalientes") -> 42 | F4: =SUMIFS(Concentrado!G$2:G$430,Concentrado!$A$2:$A$430,"="&$A4,Concentrado!$B$2:$B$430, "=Aguascalientes") -> 12
A5: 2015 | B5: =SUMIFS(Concentrado!C$2:C$430,Concentrado!$A$2:$A$430,"="&$A5,Concentrado!$B$2:$B$430, "=Aguascalientes") -> 831 | C5: =SUMIFS(Concentrado!D$2:D$430,Concentrado!$A$2:$A$430,"="&$A5,Concentrado!$B$2:$B$430, "=Aguascalientes") -> 875 | D5: =SUMIFS(Concentrado!E$2:E$430,Concentrado!$A$2:$A$430,"="&$A5,Concentrado!$B$2:$B$430, "=Aguascalientes") -> 486 | E5: =SUMIFS(Concentrado!F$2:F$430,Concentrado!$A$2:$A$430,"="&$A5,Concentrado!$B$2:$B$430, "=Aguascalientes") -> 41 | F5: =SUMIFS(Concentrado!G$2:G$430,Concentrado!$A$2:$A$430,"="&$A5,Concentrado!$B$2:$B$430, "=Aguascalientes") -> 12
A6: 2016 | B6: =SUMIFS(Concentrado!C$2:C$430,Concentrado!$A$2:$A$430,"="&$A6,Concentrado!$B$2:$B$430, "=Aguascalientes") -> 826 | C6: =SUMIFS(Concentrado!D$2:D$430,Concentrado!$A$2:$A$430,"="&$A6,Concentrado!$B$2:$B$430, "=Aguascalientes") -> 895 | D6: =SUMIFS(Concentrado!E$2:E$430,Concentrado!$A$2:$A$430,"="&$A6,Concentrado!$B$2:$B$430, "=Aguascalientes") -> 484 | E6: =SUMIFS(Concentrado!F$2:F$430,Concentrado!$A$2:$A$430,"="&$A6,Concentrado!$B$2:$B$430, "=Aguascalientes") -> 41 | F6: =SUMIFS(Concentrado!G$2:G$430,Concentrado!$A$2:$A$430,"="&$A6,Concentrado!$B$2:$B$430, "=Aguascalientes") -> 13
A7: 2017 | B7: =SUMIFS(Concentrado!C$2:C$430,Concentrado!$A$2:$A$430,"="&$A7,Concentrado!$B$2:$B$430, "=Aguascalientes") -> 843 | C7: =SUMIFS(Concentrado!D$2:D$430,Concentrado!$A$2:$A$430,"="&$A7,Concentrado!$B$2:$B$430, "=Aguascalientes") -> 875 | D7: =SUMIFS(Concentrado!E$2:E$430,Concentrado!$A$2:$A$430,"="&$A7,Concentrado!$B$2:$B$430, "=Aguascalientes") -> 472 | E7: =SUMIFS(Concentrado!F$2:F$430,Concentrado!$A$2:$A$430,"="&$A7,Concentrado!$B$2:$B$430, "=Aguascalientes") -> 42 | F7: =SUMIFS(Concentrado!G$2:G$430,Concentrado!$A$2:$A$430,"="&$A7,Concentrado!$B$2:$B$430, "=Aguascalientes") -> 13
A8: 2018 | B8: =SUMIFS(Concentrado!C$2:C$430,Concentrado!$A$2:$A$430,"="&$A8,Concentrado!$B$2:$B$430, "=Aguascalientes") -> 863 | C8: =SUMIFS(Concentrado!D$2:D$430,Concentrado!$A$2:$A$430,"="&$A8,Concentrado!$B$2:$B$430, "=Aguascalientes") -> 966 | D8: =SUMIFS(Concentrado!E$2:E$430,Concentrado!$A$2:$A$430,"="&$A8,Concentrado!$B$2:$B$430, "=Aguascalientes") -> 557 | E8: =SUMIFS(Concentrado!F$2:F$430,Concentrado!$A$2:$A$430,"="&$A8,Concentrado!$B$2:$B$430, "=Aguascalientes") -> 50 | F8: =SUMIFS(Concentrado!G$2:G$430,Concentrado!$A$2:$A$430,"="&$A8,Concentrado!$B$2:$B$430, "=Aguascalientes") -> 15
A9: 2019 | B9: =SUMIFS(Concentrado!C$2:C$430,Concentrado!$A$2:$A$430,"="&$A9,Concentrado!$B$2:$B$430, "=Aguascalientes") -> 900 | C9: =SUMIFS(Concentrado!D$2:D$430,Concentrado!$A$2:$A$430,"="&$A9,Concentrado!$B$2:$B$430, "=Aguascalientes") -> 974 | D9: =SUMIFS(Concentrado!E$2:E$430,Concentrado!$A$2:$A$430,"="&$A9,Concentrado!$B$2:$B$430, "=Aguascalientes") -> 599 | E9: =SUMIFS(Concentrado!F$2:F$430,Concentrado!$A$2:$A$430,"="&$A9,Concentrado!$B$2:$B$430, "=Aguascalientes") -> 60 | F9: =SUMIFS(Concentrado!G$2:G$430,Concentrado!$A$2:$A$430,"="&$A9,Concentrado!$B$2:$B$430, "=Aguascalientes") -> 15
A10: 2020 | B10: =SUMIFS(Concentrado!C$2:C$430,Concentrado!$A$2:$A$430,"="&$A10,Concentrado!$B$2:$B$430, "=Aguascalientes") -> 909 | C10: =SUMIFS(Concentrado!D$2:D$430,Concentrado!$A$2:$A$430,"="&$A10,Concentrado!$B$2:$B$430, "=Aguascalientes") -> 1007 | D10: =SUMIFS(Concentrado!E$2:E$430,Concentrado!$A$2:$A$430,"="&$A10,Concentrado!$B$2:$B$430, "=Aguascalientes") -> 589 | E10: =SUMIFS(Concentrado!F$2:F$430,Concentrado!$A$2:$A$430,"="&$A10,Concentrado!$B$2:$B$430, "=Aguascalientes") -> 53 | F10: =SUMIFS(Concentrado!G$2:G$430,Concentrado!$A$2:$A$430,"="&$A10,Concentrado!$B$2:$B$430, "=Aguascalientes") -> 15
A11: 2021 | B11: =SUMIFS(Concentrado!C$2:C$430,Concentrado!$A$2:$A$430,"="&$A11,Concentrado!$B$2:$B$430, "=Aguascalientes") -> 940 | C11: =SUMIFS(Concentrado!D$2:D$430,Concentrado!$A$2:$A$430,"="&$A11,Concentrado!$B$2:$B$430, "=Aguascalientes") -> 1068 | D11: =SUMIFS(Concentrado!E$2:E$430,Concentrado!$A$2:$A$430,"="&$A11,Concentrado!$B$2:$B$430, "=Aguascalientes") -> 607 | E11: =SUMIFS(Concentrado!F$2:F$430,Concentrado!$A$2:$A$430,"="&$A11,Concentrado!$B$2:$B$430, "=Aguascalientes") -> 52 | F11: =SUMIFS(Concentrado!G$2:G$430,Concentrado!$A$2:$A$430,"="&$A11,Concentrado!$B$2:$B$430, "=Aguascalientes") -> 15
A12: 2022 | B12: =SUMIFS(Concentrado!C$2:C$430,Concentrado!$A$2:$A$430,"="&$A12,Concentrado!$B$2:$B$430, "=Aguascalientes") -> 961 | C12: =SUMIFS(Concentrado!D$2:D$430,Concentrado!$A$2:$A$430,"="&$A12,Concentrado!$B$2:$B$430, "=Aguascalientes") -> 1044 | D12: =SUMIFS(Concentrado!E$2:E$430,Concentrado!$A$2:$A$430,"="&$A12,Concentrado!$B$2:$B$430, "=Aguascalientes") -> 632 | E12: =SUMIFS(Concentrado!F$2:F$430,Concentrado!$A$2:$A$430,"="&$A12,Concentrado!$B$2:$B$430, "=Aguascalientes") -> 55 | F12: =SUMIFS(Concentrado!G$2:G$430,Concentrado!$A$2:$A$430,"="&$A12,Concentrado!$B$2:$B$430, "=Aguascalientes") -> 15
A13: 2023 | B13: =SUMIFS(Concentrado!C$2:C$430,Concentrado!$A$2:$A$430,"="&$A13,Concentrado!$B$2:$B$430, "=Aguascalientes") -> 948 | C13: =SUMIFS(Concentrado!D$2:D$430,Concentrado!$A$2:$A$430,"="&$A13,Concentrado!$B$2:$B$430, "=Aguascalientes") -> 1066 | D13: =SUMIFS(Concentrado!E$2:E$430,Concentrado!$A$2:$A$430,"="&$A13,Concentrado!$B$2:$B$430, "=Aguascalientes") -> 644 | E13: =SUMIFS(Concentrado!F$2:F$430,Concentrado!$A$2:$A$430,"="&$A13,Concentrado!$B$2:$B$430, "=Aguascalientes") -> 61 | F13: =SUMIFS(Concentrado!G$2:G$430,Concentrado!$A$2:$A$430,"="&$A13,Concentrado!$B$2:$B$430, "=Aguascalientes") -> 15
A14: 2024 | B14: =SUMIFS(Concentrado!C$2:C$430,Concentrado!$A$2:$A$430,"="&$A14,Concentrado!$B$2:$B$430, "=Aguascalientes") -> 956 | C14: =SUMIFS(Concentrado!D$2:D$430,Concentrado!$A$2:$A$430,"="&$A14,Concentrado!$B$2:$B$430, "=Aguascalientes") -> 1079 | D14: =SUMIFS(Concentrado!E$2:E$430,Concentrado!$A$2:$A$430,"="&$A14,Concentrado!$B$2:$B$430, "=Aguascalientes") -> 672 | E14: =SUMIFS(Concentrado!F$2:F$430,Concentrado!$A$2:$A$430,"="&$A14,Concentrado!$B$2:$B$430, "=Aguascalientes") -> 60 | F14: =SUMIFS(Concentrado!G$2:G$430,Concentrado!$A$2:$A$430,"="&$A14,Concentrado!$B$2:$B$430, "=Aguascalientes") -> 15

Sheet BC
A1: Año | B1: Consultorios | C1: Camas hospitalarias | D1: Camas no hospitalarias | E1: Quirófanos | F1: Salas expulsión
A2: 2012 | B2: =SUMIFS(Concentrado!C$2:C430,Concentrado!$A$2:$A430,"="&$A2,Concentrado!$B$2:$B430, "=Baja California") -> 1468 | C2: =SUMIFS(Concentrado!D$2:D430,Concentrado!$A$2:$A430,"="&$A2,Concentrado!$B$2:$B430, "=Baja California") -> 2166 | D2: =SUMIFS(Concentrado!E$2:E430,Concentrado!$A$2:$A430,"="&$A2,Concentrado!$B$2:$B430, "=Baja California") -> 1089 | E2: =SUMIFS(Concentrado!F$2:F430,Concentrado!$A$2:$A430,"="&$A2,Concentrado!$B$2:$B430, "=Baja California") -> 77 | F2: =SUMIFS(Concentrado!G$2:G430,Concentrado!$A$2:$A430,"="&$A2,Concentrado!$B$2:$B430, "=Baja California") -> 46
A3: 2013 | B3: =SUMIFS(Concentrado!C$2:C431,Concentrado!$A$2:$A431,"="&$A3,Concentrado!$B$2:$B431, "=Baja California") -> 1535 | C3: =SUMIFS(Concentrado!D$2:D431,Concentrado!$A$2:$A431,"="&$A3,Concentrado!$B$2:$B431, "=Baja California") -> 2152 | D3: =SUMIFS(Concentrado!E$2:E431,Concentrado!$A$2:$A431,"="&$A3,Concentrado!$B$2:$B431, "=Baja California") -> 1150 | E3: =SUMIFS(Concentrado!F$2:F431,Concentrado!$A$2:$A431,"="&$A3,Concentrado!$B$2:$B431, "=Baja California") -> 96 | F3: =SUMIFS(Concentrado!G$2:G431,Concentrado!$A$2:$A431,"="&$A3,Concentrado!$B$2:$B431, "=Baja California") -> 44
A4: 2014 | B4: =SUMIFS(Concentrado!C$2:C432,Concentrado!$A$2:$A432,"="&$A4,Concentrado!$B$2:$B432, "=Baja California") -> 1619 | C4: =SUMIFS(Concentrado!D$2:D432,Concentrado!$A$2:$A432,"="&$A4,Concentrado!$B$2:$B432, "=Baja California") -> 2193 | D4: =SUMIFS(Concentrado!E$2:E432,Concentrado!$A$2:$A432,"="&$A4,Concentrado!$B$2:$B432, "=Baja California") -> 1271 | E4: =SUMIFS(Concentrado!F$2:F432,Concentrado!$A$2:$A432,"="&$A4,Concentrado!$B$2:$B432, "=Baja California") -> 97 | F4: =SUMIFS(Concentrado!G$2:G432,Concentrado!$A$2:$A432,"="&$A4,Concentrado!$B$2:$B432, "=Baja California") -> 42
A5: 2015 | B5: =SUMIFS(Concentrado!C$2:C433,Concentrado!$A$2:$A433,"="&$A5,Concentrado!$B$2:$B433, "=Baja California") -> 1598 | C5: =SUMIFS(Concentrado!D$2:D433,Concentrado!$A$2:$A433,"="&$A5,Concentrado!$B$2:$B433, "=Baja California") -> 2152 | D5: =SUMIFS(Concentrado!E$2:E433,Concentrado!$A$2:$A433,"="&$A5,Concentrado!$B$2:$B433, "=Baja California") -> 1076 | E5: =SUMIFS(Concentrado!F$2:F433,Concentrado!$A$2:$A433,"="&$A5,Concentrado!$B$2:$B433, "=Baja California") -> 105 | F5: =SUMIFS(Concentrado!G$2:G433,Concentrado!$A$2:$A433,"="&$A5,Concentrado!$B$2:$B433, "=Baja California") -> 42
A6: 2016 | B6: =SUMIFS(Concentrado!C$2:C434,Concentrado!$A$2:$A434,"="&$A6,Concentrado!$B$2:$B434, "=Baja California") -> 1668 | C6: =SUMIFS(Concentrado!D$2:D434,Concentrado!$A$2:$A434,"="&$A6,Concentrado!$B$2:$B434, "=Baja California") -> 2171 | D6: =SUMIFS(Concentrado!E$2:E434,Concentrado!$A$2:$A434,"="&$A6,Concentrado!$B$2:$B434, "=Baja California") -> 1056 | E6: =SUMIFS(Concentrado!F$2:F434,Concentrado!$A$2:$A434,"="&$A6,Concentrado!$B$2:$B434, "=Baja California") -> 102 | F6: =SUMIFS(Concentrado!G$2:G434,Concentrado!$A$2:$A434,"="&$A6,Concentrado!$B$2:$B434, "=Baja California") -> 39
A7: 2017 | B7: =SUMIFS(Concentrado!C$2:C435,Concentrado!$A$2:$A435,"="&$A7,Concentrado!$B$2:$B435, "=Baja California") -> 1627 | C7: =SUMIFS(Concentrado!D$2:D435,Concentrado!$A$2:$A435,"="&$A7,Concentrado!$B$2:$B435, "=Baja California") -> 2183 | D7: =SUMIFS(Concentrado!E$2:E435,Concentrado!$A$2:$A435,"="&$A7,Concentrado!$B$2:$B435, "=Baja California") -> 1036 | E7: =SUMIFS(Concentrado!F$2:F435,Concentrado!$A$2:$A435,"="&$A7,Concentrado!$B$2:$B435, "=Baja California") -> 105 | F7: =SUMIFS(Concentrado!G$2:G435,Concentrado!$A$2:$A435,"="&$A7,Concentrado!$B$2:$B435, "=Baja California") -> 39
A8: 2018 | B8: =SUMIFS(Concentrado!C$2:C436,Concentrado!$A$2:$A436,"="&$A8,Concentrado!$B$2:$B436, "=Baja California") -> 1639 | C8: =SUMIFS(Concentrado!D$2:D436,Concentrado!$A$2:$A436,"="&$A8,Concentrado!$B$2:$B436, "=Baja California") -> 2153 | D8: =SUMIFS(Concentrado!E$2:E436,Concentrado!$A$2:$A436,"="&$A8,Concentrado!$B$2:$B436, "=Baja California") -> 1069 | E8: =SUMIFS(Concentrado!F$2:F436,Concentrado!$A$2:$A436,"="&$A8,Concentrado!$B$2:$B436, "=Baja California") -> 99 | F8: =SUMIFS(Concentrado!G$2:G436,Concentrado!$A$2:$A436,"="&$A8,Concentrado!$B$2:$B436, "=Baja California") -> 41
A9: 2019 | B9: =SUMIFS(Concentrado!C$2:C437,Concentrado!$A$2:$A437,"="&$A9,Concentrado!$B$2:$B437, "=Baja California") -> 1517 | C9: =SUMIFS(Concentrado!D$2:D437,Concentrado!$A$2:$A437,"="&$A9,Concentrado!$B$2:$B437, "=Baja California") -> 2134 | D9: =SUMIFS(Concentrado!E$2:E437,Concentrado!$A$2:$A437,"="&$A9,Concentrado!$B$2:$B437, "=Baja California") -> 1070 | E9: =SUMIFS(Concentrado!F$2:F437,Concentrado!$A$2:$A437,"="&$A9,Concentrado!$B$2:$B437, "=Baja California") -> 102 | F9: =SUMIFS(Concentrado!G$2:G437,Concentrado!$A$2:$A437,"="&$A9,Concentrado!$B$2:$B437, "=Baja California") -> 38
A10: 2020 | B10: =SUMIFS(Concentrado!C$2:C438,Concentrado!$A$2:$A438,"="&$A10,Concentrado!$B$2:$B438, "=Baja California") -> 1583 | C10: =SUMIFS(Concentrado!D$2:D438,Concentrado!$A$2:$A438,"="&$A10,Concentrado!$B$2:$B438, "=Baja California") -> 2234 | D10: =SUMIFS(Concentrado!E$2:E438,Concentrado!$A$2:$A438,"="&$A10,Concentrado!$B$2:$B438, "=Baja California") -> 1132 | E10: =SUMIFS(Concentrado!F$2:F438,Concentrado!$A$2:$A438,"="&$A10,Concentrado!$B$2:$B438, "=Baja California") -> 101 | F10: =SUMIFS(Concentrado!G$2:G438,Concentrado!$A$2:$A438,"="&$A10,Concentrado!$B$2:$B438, "=Baja California") -> 39
A11: 2021 | B11: =SUMIFS(Concentrado!C$2:C439,Concentrado!$A$2:$A439,"="&$A11,Concentrado!$B$2:$B439, "=Baja California") -> 1623 | C11: =SUMIFS(Concentrado!D$2:D439,Concentrado!$A$2:$A439,"="&$A11,Concentrado!$B$2:$B439, "=Baja California") -> 2219 | D11: =SUMIFS(Concentrado!E$2:E439,Concentrado!$A$2:$A439,"="&$A11,Concentrado!$B$2:$B439, "=Baja California") -> 1128 | E11: =SUMIFS(Concentrado!F$2:F439,Concentrado!$A$2:$A439,"="&$A11,Concentrado!$B$2:$B439, "=Baja California") -> 100 | F11: =SUMIFS(Concentrado!G$2:G439,Concentrado!$A$2:$A439,"="&$A11,Concentrado!$B$2:$B439, "=Baja California") -> 39
A12: 2022 | B12: =SUMIFS(Concentrado!C$2:C440,Concentrado!$A$2:$A440,"="&$A12,Concentrado!$B$2:$B440, "=Baja California") -> 1708 | C12: =SUMIFS(Concentrado!D$2:D440,Concentrado!$A$2:$A440,"="&$A12,Concentrado!$B$2:$B440, "=Baja California") -> 2349 | D12: =SUMIFS(Concentrado!E$2:E440,Concentrado!$A$2:$A440,"="&$A12,Concentrado!$B$2:$B440, "=Baja California") -> 1097 | E12: =SUMIFS(Concentrado!F$2:F440,Concentrado!$A$2:$A440,"="&$A12,Concentrado!$B$2:$B440, "=Baja California") -> 105 | F12: =SUMIFS(Concentrado!G$2:G440,Concentrado!$A$2:$A440,"="&$A12,Concentrado!$B$2:$B440, "=Baja California") -> 37
A13: 2023 | B13: =SUMIFS(Concentrado!C$2:C441,Concentrado!$A$2:$A441,"="&$A13,Concentrado!$B$2:$B441, "=Baja California") -> 1687 | C13: =SUMIFS(Concentrado!D$2:D441,Concentrado!$A$2:$A441,"="&$A13,Concentrado!$B$2:$B441, "=Baja California") -> 2378 | D13: =SUMIFS(Concentrado!E$2:E441,Concentrado!$A$2:$A441,"="&$A13,Concentrado!$B$2:$B441, "=Baja California") -> 1118 | E13: =SUMIFS(Concentrado!F$2:F441,Concentrado!$A$2:$A441,"="&$A13,Concentrado!$B$2:$B441, "=Baja California") -> 99 | F13: =SUMIFS(Concentrado!G$2:G441,Concentrado!$A$2:$A441,"="&$A13,Concentrado!$B$2:$B441, "=Baja California") -> 38
A14: 2024 | B14: =SUMIFS(Concentrado!C$2:C442,Concentrado!$A$2:$A442,"="&$A14,Concentrado!$B$2:$B442, "=Baja California") -> 1767 | C14: =SUMIFS(Concentrado!D$2:D442,Concentrado!$A$2:$A442,"="&$A14,Concentrado!$B$2:$B442, "=Baja California") -> 2606 | D14: =SUMIFS(Concentrado!E$2:E442,Concentrado!$A$2:$A442,"="&$A14,Concentrado!$B$2:$B442, "=Baja California") -> 1222 | E14: =SUMIFS(Concentrado!F$2:F442,Concentrado!$A$2:$A442,"="&$A14,Concentrado!$B$2:$B442, "=Baja California") -> 109 | F14: =SUMIFS(Concentrado!G$2:G442,Concentrado!$A$2:$A442,"="&$A14,Concentrado!$B$2:$B442, "=Baja California") -> 37

Sheet BCS
A1: Año | B1: Consultorios | C1: Camas hospitalarias | D1: Camas no hospitalarias | E1: Quirófanos | F1: Salas expulsión
A2: 2012 | B2: =SUMIFS(Concentrado!C$2:C430,Concentrado!$A$2:$A430,"="&$A2,Concentrado!$B$2:$B430, "=Baja California Sur") -> 549 | C2: =SUMIFS(Concentrado!D$2:D430,Concentrado!$A$2:$A430,"="&$A2,Concentrado!$B$2:$B430, "=Baja California Sur") -> 673 | D2: =SUMIFS(Concentrado!E$2:E430,Concentrado!$A$2:$A430,"="&$A2,Concentrado!$B$2:$B430, "=Baja California Sur") -> 514 | E2: =SUMIFS(Concentrado!F$2:F430,Concentrado!$A$2:$A430,"="&$A2,Concentrado!$B$2:$B430, "=Baja California Sur") -> 31 | F2: =SUMIFS(Concentrado!G$2:G430,Concentrado!$A$2:$A430,"="&$A2,Concentrado!$B$2:$B430, "=Baja California Sur") -> 26
A3: 2013 | B3: =SUMIFS(Concentrado!C$2:C431,Concentrado!$A$2:$A431,"="&$A3,Concentrado!$B$2:$B431, "=Baja California Sur") -> 597 | C3: =SUMIFS(Concentrado!D$2:D431,Concentrado!$A$2:$A431,"="&$A3,Concentrado!$B$2:$B431, "=Baja California Sur") -> 674 | D3: =SUMIFS(Concentrado!E$2:E431,Concentrado!$A$2:$A431,"="&$A3,Concentrado!$B$2:$B431, "=Baja California Sur") -> 548 | E3: =SUMIFS(Concentrado!F$2:F431,Concentrado!$A$2:$A431,"="&$A3,Concentrado!$B$2:$B431, "=Baja California Sur") -> 36 | F3: =SUMIFS(Concentrado!G$2:G431,Concentrado!$A$2:$A431,"="&$A3,Concentrado!$B$2:$B431, "=Baja California Sur") -> 26
A4: 2014 | B4: =SUMIFS(Concentrado!C$2:C432,Concentrado!$A$2:$A432,"="&$A4,Concentrado!$B$2:$B432, "=Baja California Sur") -> 618 | C4: =SUMIFS(Concentrado!D$2:D432,Concentrado!$A$2:$A432,"="&$A4,Concentrado!$B$2:$B432, "=Baja California Sur") -> 678 | D4: =SUMIFS(Concentrado!E$2:E432,Concentrado!$A$2:$A432,"="&$A4,Concentrado!$B$2:$B432, "=Baja California Sur") -> 530 | E4: =SUMIFS(Concentrado!F$2:F432,Concentrado!$A$2:$A432,"="&$A4,Concentrado!$B$2:$B432, "=Baja California Sur") -> 38 | F4: =SUMIFS(Concentrado!G$2:G432,Concentrado!$A$2:$A432,"="&$A4,Concentrado!$B$2:$B432, "=Baja California Sur") -> 26
A5: 2015 | B5: =SUMIFS(Concentrado!C$2:C433,Concentrado!$A$2:$A433,"="&$A5,Concentrado!$B$2:$B433, "=Baja California Sur") -> 613 | C5: =SUMIFS(Concentrado!D$2:D433,Concentrado!$A$2:$A433,"="&$A5,Concentrado!$B$2:$B433, "=Baja California Sur") -> 679 | D5: =SUMIFS(Concentrado!E$2:E433,Concentrado!$A$2:$A433,"="&$A5,Concentrado!$B$2:$B433, "=Baja California Sur") -> 462 | E5: =SUMIFS(Concentrado!F$2:F433,Concentrado!$A$2:$A433,"="&$A5,Concentrado!$B$2:$B433, "=Baja California Sur") -> 38 | F5: =SUMIFS(Concentrado!G$2:G433,Concentrado!$A$2:$A433,"="&$A5,Concentrado!$B$2:$B433, "=Baja California Sur") -> 25
A6: 2016 | B6: =SUMIFS(Concentrado!C$2:C434,Concentrado!$A$2:$A434,"="&$A6,Concentrado!$B$2:$B434, "=Baja California Sur") -> 606 | C6: =SUMIFS(Concentrado!D$2:D434,Concentrado!$A$2:$A434,"="&$A6,Concentrado!$B$2:$B434, "=Baja California Sur") -> 695 | D6: =SUMIFS(Concentrado!E$2:E434,Concentrado!$A$2:$A434,"="&$A6,Concentrado!$B$2:$B434, "=Baja California Sur") -> 449 | E6: =SUMIFS(Concentrado!F$2:F434,Concentrado!$A$2:$A434,"="&$A6,Concentrado!$B$2:$B434, "=Baja California Sur") -> 38 | F6: =SUMIFS(Concentrado!G$2:G434,Concentrado!$A$2:$A434,"="&$A6,Concentrado!$B$2:$B434, "=Baja California Sur") -> 32
A7: 2017 | B7: =SUMIFS(Concentrado!C$2:C435,Concentrado!$A$2:$A435,"="&$A7,Concentrado!$B$2:$B435, "=Baja California Sur") -> 628 | C7: =SUMIFS(Concentrado!D$2:D435,Concentrado!$A$2:$A435,"="&$A7,Concentrado!$B$2:$B435, "=Baja California Sur") -> 690 | D7: =SUMIFS(Concentrado!E$2:E435,Concentrado!$A$2:$A435,"="&$A7,Concentrado!$B$2:$B435, "=Baja California Sur") -> 435 | E7: =SUMIFS(Concentrado!F$2:F435,Concentrado!$A$2:$A435,"="&$A7,Concentrado!$B$2:$B435, "=Baja California Sur") -> 38 | F7: =SUMIFS(Concentrado!G$2:G435,Concentrado!$A$2:$A435,"="&$A7,Concentrado!$B$2:$B435, "=Baja California Sur") -> 32
A8: 2018 | B8: =SUMIFS(Concentrado!C$2:C436,Concentrado!$A$2:$A436,"="&$A8,Concentrado!$B$2:$B436, "=Baja California Sur") -> 631 | C8: =SUMIFS(Concentrado!D$2:D436,Concentrado!$A$2:$A436,"="&$A8,Concentrado!$B$2:$B436, "=Baja California Sur") -> 695 | D8: =SUMIFS(Concentrado!E$2:E436,Concentrado!$A$2:$A436,"="&$A8,Concentrado!$B$2:$B436, "=Baja California Sur") -> 420 | E8: =SUMIFS(Concentrado!F$2:F436,Concentrado!$A$2:$A436,"="&$A8,Concentrado!$B$2:$B436, "=Baja California Sur") -> 38 | F8: =SUMIFS(Concentrado!G$2:G436,Concentrado!$A$2:$A436,"="&$A8,Concentrado!$B$2:$B436, "=Baja California Sur") -> 31
A9: 2019 | B9: =SUMIFS(Concentrado!C$2:C437,Concentrado!$A$2:$A437,"="&$A9,Concentrado!$B$2:$B437, "=Baja California Sur") -> 660 | C9: =SUMIFS(Concentrado!D$2:D437,Concentrado!$A$2:$A437,"="&$A9,Concentrado!$B$2:$B437, "=Baja California Sur") -> 713 | D9: =SUMIFS(Concentrado!E$2:E437,Concentrado!$A$2:$A437,"="&$A9,Concentrado!$B$2:$B437, "=Baja California Sur") -> 452 | E9: =SUMIFS(Concentrado!F$2:F437,Concentrado!$A$2:$A437,"="&$A9,Concentrado!$B$2:$B437, "=Baja California Sur") -> 37 | F9: =SUMIFS(Concentrado!G$2:G437,Concentrado!$A$2:$A437,"="&$A9,Concentrado!$B$2:$B437, "=Baja California Sur") -> 32
A10: 2020 | B10: =SUMIFS(Concentrado!C$2:C438,Concentrado!$A$2:$A438,"="&$A10,Concentrado!$B$2:$B438, "=Baja California Sur") -> 673 | C10: =SUMIFS(Concentrado!D$2:D438,Concentrado!$A$2:$A438,"="&$A10,Concentrado!$B$2:$B438, "=Baja California Sur") -> 756 | D10: =SUMIFS(Concentrado!E$2:E438,Concentrado!$A$2:$A438,"="&$A10,Concentrado!$B$2:$B438, "=Baja California Sur") -> 453 | E10: =SUMIFS(Concentrado!F$2:F438,Concentrado!$A$2:$A438,"="&$A10,Concentrado!$B$2:$B438, "=Baja California Sur") -> 35 | F10: =SUMIFS(Concentrado!G$2:G438,Concentrado!$A$2:$A438,"="&$A10,Concentrado!$B$2:$B438, "=Baja California Sur") -> 33
A11: 2021 | B11: =SUMIFS(Concentrado!C$2:C439,Concentrado!$A$2:$A439,"="&$A11,Concentrado!$B$2:$B439, "=Baja California Sur") -> 666 | C11: =SUMIFS(Concentrado!D$2:D439,Concentrado!$A$2:$A439,"="&$A11,Concentrado!$B$2:$B439, "=Baja California Sur") -> 721 | D11: =SUMIFS(Concentrado!E$2:E439,Concentrado!$A$2:$A439,"="&$A11,Concentrado!$B$2:$B439, "=Baja California Sur") -> 445 | E11: =SUMIFS(Concentrado!F$2:F439,Concentrado!$A$2:$A439,"="&$A11,Concentrado!$B$2:$B439, "=Baja California Sur") -> 38 | F11: =SUMIFS(Concentrado!G$2:G439,Concentrado!$A$2:$A439,"="&$A11,Concentrado!$B$2:$B439, "=Baja California Sur") -> 35
A12: 2022 | B12: =SUMIFS(Concentrado!C$2:C440,Concentrado!$A$2:$A440,"="&$A12,Concentrado!$B$2:$B440, "=Baja California Sur") -> 647 | C12: =SUMIFS(Concentrado!D$2:D440,Concentrado!$A$2:$A440,"="&$A12,Concentrado!$B$2:$B440, "=Baja California Sur") -> 813 | D12: =SUMIFS(Concentrado!E$2:E440,Concentrado!$A$2:$A440,"="&$A12,Concentrado!$B$2:$B440, "=Baja California Sur") -> 439 | E12: =SUMIFS(Concentrado!F$2:F440,Concentrado!$A$2:$A440,"="&$A12,Concentrado!$B$2:$B440, "=Baja California Sur") -> 38 | F12: =SUMIFS(Concentrado!G$2:G440,Concentrado!$A$2:$A440,"="&$A12,Concentrado!$B$2:$B440, "=Baja California Sur") -> 27
A13: 2023 | B13: =SUMIFS(Concentrado!C$2:C441,Concentrado!$A$2:$A441,"="&$A13,Concentrado!$B$2:$B441, "=Baja California Sur") -> 714 | C13: =SUMIFS(Concentrado!D$2:D441,Concentrado!$A$2:$A441,"="&$A13,Concentrado!$B$2:$B441, "=Baja California Sur") -> 859 | D13: =SUMIFS(Concentrado!E$2:E441,Concentrado!$A$2:$A441,"="&$A13,Concentrado!$B$2:$B441, "=Baja California Sur") -> 483 | E13: =SUMIFS(Concentrado!F$2:F441,Concentrado!$A$2:$A441,"="&$A13,Concentrado!$B$2:$B441, "=Baja California Sur") -> 43 | F13: =SUMIFS(Concentrado!G$2:G441,Concentrado!$A$2:$A441,"="&$A13,Concentrado!$B$2:$B441, "=Baja California Sur") -> 29
A14: 2024 | B14: =SUMIFS(Concentrado!C$2:C442,Concentrado!$A$2:$A442,"="&$A14,Concentrado!$B$2:$B442, "=Baja California Sur") -> 714 | C14: =SUMIFS(Concentrado!D$2:D442,Concentrado!$A$2:$A442,"="&$A14,Concentrado!$B$2:$B442, "=Baja California Sur") -> 892 | D14: =SUMIFS(Concentrado!E$2:E442,Concentrado!$A$2:$A442,"="&$A14,Concentrado!$B$2:$B442, "=Baja California Sur") -> 509 | E14: =SUMIFS(Concentrado!F$2:F442,Concentrado!$A$2:$A442,"="&$A14,Concentrado!$B$2:$B442, "=Baja California Sur") -> 45 | F14: =SUMIFS(Concentrado!G$2:G442,Concentrado!$A$2:$A442,"="&$A14,Concentrado!$B$2:$B442, "=Baja California Sur") -> 24

Sheet CAMP
A1: Año | B1: Consultorios | C1: Camas hospitalarias | D1: Camas no hospitalarias | E1: Quirófanos | F1: Salas expulsión
A2: 2012 | B2: =SUMIFS(Concentrado!C$2:C430,Concentrado!$A$2:$A430,"="&$A2,Concentrado!$B$2:$B430, "=Campeche") -> 791 | C2: =SUMIFS(Concentrado!D$2:D430,Concentrado!$A$2:$A430,"="&$A2,Concentrado!$B$2:$B430, "=Campeche") -> 860 | D2: =SUMIFS(Concentrado!E$2:E430,Concentrado!$A$2:$A430,"="&$A2,Concentrado!$B$2:$B430, "=Campeche") -> 549 | E2: =SUMIFS(Concentrado!F$2:F430,Concentrado!$A$2:$A430,"="&$A2,Concentrado!$B$2:$B430, "=Campeche") -> 35 | F2: =SUMIFS(Concentrado!G$2:G430,Concentrado!$A$2:$A430,"="&$A2,Concentrado!$B$2:$B430, "=Campeche") -> 24
A3: 2013 | B3: =SUMIFS(Concentrado!C$2:C431,Concentrado!$A$2:$A431,"="&$A3,Concentrado!$B$2:$B431, "=Campeche") -> 828 | C3: =SUMIFS(Concentrado!D$2:D431,Concentrado!$A$2:$A431,"="&$A3,Concentrado!$B$2:$B431, "=Campeche") -> 945 | D3: =SUMIFS(Concentrado!E$2:E431,Concentrado!$A$2:$A431,"="&$A3,Concentrado!$B$2:$B431, "=Campeche") -> 609 | E3: =SUMIFS(Concentrado!F$2:F431,Concentrado!$A$2:$A431,"="&$A3,Concentrado!$B$2:$B431, "=Campeche") -> 40 | F3: =SUMIFS(Concentrado!G$2:G431,Concentrado!$A$2:$A431,"="&$A3,Concentrado!$B$2:$B431, "=Campeche") -> 25
A4: 2014 | B4: =SUMIFS(Concentrado!C$2:C432,Concentrado!$A$2:$A432,"="&$A4,Concentrado!$B$2:$B432, "=Campeche") -> 820 | C4: =SUMIFS(Concentrado!D$2:D432,Concentrado!$A$2:$A432,"="&$A4,Concentrado!$B$2:$B432, "=Campeche") -> 939 | D4: =SUMIFS(Concentrado!E$2:E432,Concentrado!$A$2:$A432,"="&$A4,Concentrado!$B$2:$B432, "=Campeche") -> 618 | E4: =SUMIFS(Concentrado!F$2:F432,Concentrado!$A$2:$A432,"="&$A4,Concentrado!$B$2:$B432, "=Campeche") -> 39 | F4: =SUMIFS(Concentrado!G$2:G432,Concentrado!$A$2:$A432,"="&$A4,Concentrado!$B$2:$B432, "=Campeche") -> 25
A5: 2015 | B5: =SUMIFS(Concentrado!C$2:C433,Concentrado!$A$2:$A433,"="&$A5,Concentrado!$B$2:$B433, "=Campeche") -> 774 | C5: =SUMIFS(Concentrado!D$2:D433,Concentrado!$A$2:$A433,"="&$A5,Concentrado!$B$2:$B433, "=Campeche") -> 779 | D5: =SUMIFS(Concentrado!E$2:E433,Concentrado!$A$2:$A433,"="&$A5,Concentrado!$B$2:$B433, "=Campeche") -> 537 | E5: =SUMIFS(Concentrado!F$2:F433,Concentrado!$A$2:$A433,"="&$A5,Concentrado!$B$2:$B433, "=Campeche") -> 38 | F5: =SUMIFS(Concentrado!G$2:G433,Concentrado!$A$2:$A433,"="&$A5,Concentrado!$B$2:$B433, "=Campeche") -> 24
A6: 2016 | B6: =SUMIFS(Concentrado!C$2:C434,Concentrado!$A$2:$A434,"="&$A6,Concentrado!$B$2:$B434, "=Campeche") -> 787 | C6: =SUMIFS(Concentrado!D$2:D434,Concentrado!$A$2:$A434,"="&$A6,Concentrado!$B$2:$B434, "=Campeche") -> 789 | D6: =SUMIFS(Concentrado!E$2:E434,Concentrado!$A$2:$A434,"="&$A6,Concentrado!$B$2:$B434, "=Campeche") -> 544 | E6: =SUMIFS(Concentrado!F$2:F434,Concentrado!$A$2:$A434,"="&$A6,Concentrado!$B$2:$B434, "=Campeche") -> 37 | F6: =SUMIFS(Concentrado!G$2:G434,Concentrado!$A$2:$A434,"="&$A6,Concentrado!$B$2:$B434, "=Campeche") -> 31
A7: 2017 | B7: =SUMIFS(Concentrado!C$2:C435,Concentrado!$A$2:$A435,"="&$A7,Concentrado!$B$2:$B435, "=Campeche") -> 804 | C7: =SUMIFS(Concentrado!D$2:D435,Concentrado!$A$2:$A435,"="&$A7,Concentrado!$B$2:$B435, "=Campeche") -> 764 | D7: =SUMIFS(Concentrado!E$2:E435,Concentrado!$A$2:$A435,"="&$A7,Concentrado!$B$2:$B435, "=Campeche") -> 549 | E7: =SUMIFS(Concentrado!F$2:F435,Concentrado!$A$2:$A435,"="&$A7,Concentrado!$B$2:$B435, "=Campeche") -> 45 | F7: =SUMIFS(Concentrado!G$2:G435,Concentrado!$A$2:$A435,"="&$A7,Concentrado!$B$2:$B435, "=Campeche") -> 30
A8: 2018 | B8: =SUMIFS(Concentrado!C$2:C436,Concentrado!$A$2:$A436,"="&$A8,Concentrado!$B$2:$B436, "=Campeche") -> 811 | C8: =SUMIFS(Concentrado!D$2:D436,Concentrado!$A$2:$A436,"="&$A8,Concentrado!$B$2:$B436, "=Campeche") -> 790 | D8: =SUMIFS(Concentrado!E$2:E436,Concentrado!$A$2:$A436,"="&$A8,Concentrado!$B$2:$B436, "=Campeche") -> 539 | E8: =SUMIFS(Concentrado!F$2:F436,Concentrado!$A$2:$A436,"="&$A8,Concentrado!$B$2:$B436, "=Campeche") -> 40 | F8: =SUMIFS(Concentrado!G$2:G436,Concentrado!$A$2:$A436,"="&$A8,Concentrado!$B$2:$B436, "=Campeche") -> 28
A9: 2019 | B9: =SUMIFS(Concentrado!C$2:C437,Concentrado!$A$2:$A437,"="&$A9,Concentrado!$B$2:$B437, "=Campeche") -> 777 | C9: =SUMIFS(Concentrado!D$2:D437,Concentrado!$A$2:$A437,"="&$A9,Concentrado!$B$2:$B437, "=Campeche") -> 802 | D9: =SUMIFS(Concentrado!E$2:E437,Concentrado!$A$2:$A437,"="&$A9,Concentrado!$B$2:$B437, "=Campeche") -> 587 | E9: =SUMIFS(Concentrado!F$2:F437,Concentrado!$A$2:$A437,"="&$A9,Concentrado!$B$2:$B437, "=Campeche") -> 41 | F9: =SUMIFS(Concentrado!G$2:G437,Concentrado!$A$2:$A437,"="&$A9,Concentrado!$B$2:$B437, "=Campeche") -> 24
A10: 2020 | B10: =SUMIFS(Concentrado!C$2:C438,Concentrado!$A$2:$A438,"="&$A10,Concentrado!$B$2:$B438, "=Campeche") -> 808 | C10: =SUMIFS(Concentrado!D$2:D438,Concentrado!$A$2:$A438,"="&$A10,Concentrado!$B$2:$B438, "=Campeche") -> 843 | D10: =SUMIFS(Concentrado!E$2:E438,Concentrado!$A$2:$A438,"="&$A10,Concentrado!$B$2:$B438, "=Campeche") -> 564 | E10: =SUMIFS(Concentrado!F$2:F438,Concentrado!$A$2:$A438,"="&$A10,Concentrado!$B$2:$B438, "=Campeche") -> 39 | F10: =SUMIFS(Concentrado!G$2:G438,Concentrado!$A$2:$A438,"="&$A10,Concentrado!$B$2:$B438, "=Campeche") -> 21
A11: 2021 | B11: =SUMIFS(Concentrado!C$2:C439,Concentrado!$A$2:$A439,"="&$A11,Concentrado!$B$2:$B439, "=Campeche") -> 764 | C11: =SUMIFS(Concentrado!D$2:D439,Concentrado!$A$2:$A439,"="&$A11,Concentrado!$B$2:$B439, "=Campeche") -> 860 | D11: =SUMIFS(Concentrado!E$2:E439,Concentrado!$A$2:$A439,"="&$A11,Concentrado!$B$2:$B439, "=Campeche") -> 561 | E11: =SUMIFS(Concentrado!F$2:F439,Concentrado!$A$2:$A439,"="&$A11,Concentrado!$B$2:$B439, "=Campeche") -> 40 | F11: =SUMIFS(Concentrado!G$2:G439,Concentrado!$A$2:$A439,"="&$A11,Concentrado!$B$2:$B439, "=Campeche") -> 22
A12: 2022 | B12: =SUMIFS(Concentrado!C$2:C440,Concentrado!$A$2:$A440,"="&$A12,Concentrado!$B$2:$B440, "=Campeche") -> 815 | C12: =SUMIFS(Concentrado!D$2:D440,Concentrado!$A$2:$A440,"="&$A12,Concentrado!$B$2:$B440, "=Campeche") -> 927 | D12: =SUMIFS(Concentrado!E$2:E440,Concentrado!$A$2:$A440,"="&$A12,Concentrado!$B$2:$B440, "=Campeche") -> 555 | E12: =SUMIFS(Concentrado!F$2:F440,Concentrado!$A$2:$A440,"="&$A12,Concentrado!$B$2:$B440, "=Campeche") -> 44 | F12: =SUMIFS(Concentrado!G$2:G440,Concentrado!$A$2:$A440,"="&$A12,Concentrado!$B$2:$B440, "=Campeche") -> 22
A13: 2023 | B13: =SUMIFS(Concentrado!C$2:C441,Concentrado!$A$2:$A441,"="&$A13,Concentrado!$B$2:$B441, "=Campeche") -> 799 | C13: =SUMIFS(Concentrado!D$2:D441,Concentrado!$A$2:$A441,"="&$A13,Concentrado!$B$2:$B441, "=Campeche") -> 847 | D13: =SUMIFS(Concentrado!E$2:E441,Concentrado!$A$2:$A441,"="&$A13,Concentrado!$B$2:$B441, "=Campeche") -> 583 | E13: =SUMIFS(Concentrado!F$2:F441,Concentrado!$A$2:$A441,"="&$A13,Concentrado!$B$2:$B441, "=Campeche") -> 45 | F13: =SUMIFS(Concentrado!G$2:G441,Concentrado!$A$2:$A441,"="&$A13,Concentrado!$B$2:$B441, "=Campeche") -> 23
A14: 2024 | B14: =SUMIFS(Concentrado!C$2:C442,Concentrado!$A$2:$A442,"="&$A14,Concentrado!$B$2:$B442, "=Campeche") -> 834 | C14: =SUMIFS(Concentrado!D$2:D442,Concentrado!$A$2:$A442,"="&$A14,Concentrado!$B$2:$B442, "=Campeche") -> 847 | D14: =SUMIFS(Concentrado!E$2:E442,Concentrado!$A$2:$A442,"="&$A14,Concentrado!$B$2:$B442, "=Campeche") -> 598 | E14: =SUMIFS(Concentrado!F$2:F442,Concentrado!$A$2:$A442,"="&$A14,Concentrado!$B$2:$B442, "=Campeche") -> 47 | F14: =SUMIFS(Concentrado!G$2:G442,Concentrado!$A$2:$A442,"="&$A14,Concentrado!$B$2:$B442, "=Campeche") -> 23

Sheet CHIS
A1: Año | B1: Consultorios | C1: Camas hospitalarias | D1: Camas no hospitalarias | E1: Quirófanos | F1: Salas expulsión
A2: 2012 | B2: =SUMIFS(Concentrado!C$2:C430,Concentrado!$A$2:$A430,"="&$A2,Concentrado!$B$2:$B430, "=Chiapas") -> 2732 | C2: =SUMIFS(Concentrado!D$2:D430,Concentrado!$A$2:$A430,"="&$A2,Concentrado!$B$2:$B430, "=Chiapas") -> 2077 | D2: =SUMIFS(Concentrado!E$2:E430,Concentrado!$A$2:$A430,"="&$A2,Concentrado!$B$2:$B430, "=Chiapas") -> 2528 | E2: =SUMIFS(Concentrado!F$2:F430,Concentrado!$A$2:$A430,"="&$A2,Concentrado!$B$2:$B430, "=Chiapas") -> 121 | F2: =SUMIFS(Concentrado!G$2:G430,Concentrado!$A$2:$A430,"="&$A2,Concentrado!$B$2:$B430, "=Chiapas") -> 84
A3: 2013 | B3: =SUMIFS(Concentrado!C$2:C431,Concentrado!$A$2:$A431,"="&$A3,Concentrado!$B$2:$B431, "=Chiapas") -> 2867 | C3: =SUMIFS(Concentrado!D$2:D431,Concentrado!$A$2:$A431,"="&$A3,Concentrado!$B$2:$B431, "=Chiapas") -> 2226 | D3: =SUMIFS(Concentrado!E$2:E431,Concentrado!$A$2:$A431,"="&$A3,Concentrado!$B$2:$B431, "=Chiapas") -> 2616 | E3: =SUMIFS(Concentrado!F$2:F431,Concentrado!$A$2:$A431,"="&$A3,Concentrado!$B$2:$B431, "=Chiapas") -> 129 | F3: =SUMIFS(Concentrado!G$2:G431,Concentrado!$A$2:$A431,"="&$A3,Concentrado!$B$2:$B431, "=Chiapas") -> 87
A4: 2014 | B4: =SUMIFS(Concentrado!C$2:C432,Concentrado!$A$2:$A432,"="&$A4,Concentrado!$B$2:$B432, "=Chiapas") -> 2963 | C4: =SUMIFS(Concentrado!D$2:D432,Concentrado!$A$2:$A432,"="&$A4,Concentrado!$B$2:$B432, "=Chiapas") -> 2240 | D4: =SUMIFS(Concentrado!E$2:E432,Concentrado!$A$2:$A432,"="&$A4,Concentrado!$B$2:$B432, "=Chiapas") -> 2664 | E4: =SUMIFS(Concentrado!F$2:F432,Concentrado!$A$2:$A432,"="&$A4,Concentrado!$B$2:$B432, "=Chiapas") -> 128 | F4: =SUMIFS(Concentrado!G$2:G432,Concentrado!$A$2:$A432,"="&$A4,Concentrado!$B$2:$B432, "=Chiapas") -> 92
A5: 2015 | B5: =SUMIFS(Concentrado!C$2:C433,Concentrado!$A$2:$A433,"="&$A5,Concentrado!$B$2:$B433, "=Chiapas") -> 3011 | C5: =SUMIFS(Concentrado!D$2:D433,Concentrado!$A$2:$A433,"="&$A5,Concentrado!$B$2:$B433, "=Chiapas") -> 2193 | D5: =SUMIFS(Concentrado!E$2:E433,Concentrado!$A$2:$A433,"="&$A5,Concentrado!$B$2:$B433, "=Chiapas") -> 1629 | E5: =SUMIFS(Concentrado!F$2:F433,Concentrado!$A$2:$A433,"="&$A5,Concentrado!$B$2:$B433, "=Chiapas") -> 133 | F5: =SUMIFS(Concentrado!G$2:G433,Concentrado!$A$2:$A433,"="&$A5,Concentrado!$B$2:$B433, "=Chiapas") -> 95
A6: 2016 | B6: =SUMIFS(Concentrado!C$2:C434,Concentrado!$A$2:$A434,"="&$A6,Concentrado!$B$2:$B434, "=Chiapas") -> 3064 | C6: =SUMIFS(Concentrado!D$2:D434,Concentrado!$A$2:$A434,"="&$A6,Concentrado!$B$2:$B434, "=Chiapas") -> 2350 | D6: =SUMIFS(Concentrado!E$2:E434,Concentrado!$A$2:$A434,"="&$A6,Concentrado!$B$2:$B434, "=Chiapas") -> 1690 | E6: =SUMIFS(Concentrado!F$2:F434,Concentrado!$A$2:$A434,"="&$A6,Concentrado!$B$2:$B434, "=Chiapas") -> 136 | F6: =SUMIFS(Concentrado!G$2:G434,Concentrado!$A$2:$A434,"="&$A6,Concentrado!$B$2:$B434, "=Chiapas") -> 93
A7: 2017 | B7: =SUMIFS(Concentrado!C$2:C435,Concentrado!$A$2:$A435,"="&$A7,Concentrado!$B$2:$B435, "=Chiapas") -> 3020 | C7: =SUMIFS(Concentrado!D$2:D435,Concentrado!$A$2:$A435,"="&$A7,Concentrado!$B$2:$B435, "=Chiapas") -> 2412 | D7: =SUMIFS(Concentrado!E$2:E435,Concentrado!$A$2:$A435,"="&$A7,Concentrado!$B$2:$B435, "=Chiapas") -> 1561 | E7: =SUMIFS(Concentrado!F$2:F435,Concentrado!$A$2:$A435,"="&$A7,Concentrado!$B$2:$B435, "=Chiapas") -> 142 | F7: =SUMIFS(Concentrado!G$2:G435,Concentrado!$A$2:$A435,"="&$A7,Concentrado!$B$2:$B435, "=Chiapas") -> 94
A8: 2018 | B8: =SUMIFS(Concentrado!C$2:C436,Concentrado!$A$2:$A436,"="&$A8,Concentrado!$B$2:$B436, "=Chiapas") -> 3122 | C8: =SUMIFS(Concentrado!D$2:D436,Concentrado!$A$2:$A436,"="&$A8,Concentrado!$B$2:$B436, "=Chiapas") -> 2260 | D8: =SUMIFS(Concentrado!E$2:E436,Concentrado!$A$2:$A436,"="&$A8,Concentrado!$B$2:$B436, "=Chiapas") -> 1589 | E8: =SUMIFS(Concentrado!F$2:F436,Concentrado!$A$2:$A436,"="&$A8,Concentrado!$B$2:$B436, "=Chiapas") -> 146 | F8: =SUMIFS(Concentrado!G$2:G436,Concentrado!$A$2:$A436,"="&$A8,Concentrado!$B$2:$B436, "=Chiapas") -> 94
A9: 2019 | B9: =SUMIFS(Concentrado!C$2:C437,Concentrado!$A$2:$A437,"="&$A9,Concentrado!$B$2:$B437, "=Chiapas") -> 3098 | C9: =SUMIFS(Concentrado!D$2:D437,Concentrado!$A$2:$A437,"="&$A9,Concentrado!$B$2:$B437, "=Chiapas") -> 2252 | D9: =SUMIFS(Concentrado!E$2:E437,Concentrado!$A$2:$A437,"="&$A9,Concentrado!$B$2:$B437, "=Chiapas") -> 1636 | E9: =SUMIFS(Concentrado!F$2:F437,Concentrado!$A$2:$A437,"="&$A9,Concentrado!$B$2:$B437, "=Chiapas") -> 151 | F9: =SUMIFS(Concentrado!G$2:G437,Concentrado!$A$2:$A437,"="&$A9,Concentrado!$B$2:$B437, "=Chiapas") -> 97
A10: 2020 | B10: =SUMIFS(Concentrado!C$2:C438,Concentrado!$A$2:$A438,"="&$A10,Concentrado!$B$2:$B438, "=Chiapas") -> 3164 | C10: =SUMIFS(Concentrado!D$2:D438,Concentrado!$A$2:$A438,"="&$A10,Concentrado!$B$2:$B438, "=Chiapas") -> 2495 | D10: =SUMIFS(Concentrado!E$2:E438,Concentrado!$A$2:$A438,"="&$A10,Concentrado!$B$2:$B438, "=Chiapas") -> 1638 | E10: =SUMIFS(Concentrado!F$2:F438,Concentrado!$A$2:$A438,"="&$A10,Concentrado!$B$2:$B438, "=Chiapas") -> 145 | F10: =SUMIFS(Concentrado!G$2:G438,Concentrado!$A$2:$A438,"="&$A10,Concentrado!$B$2:$B438, "=Chiapas") -> 101
A11: 2021 | B11: =SUMIFS(Concentrado!C$2:C439,Concentrado!$A$2:$A439,"="&$A11,Concentrado!$B$2:$B439, "=Chiapas") -> 3242 | C11: =SUMIFS(Concentrado!D$2:D439,Concentrado!$A$2:$A439,"="&$A11,Concentrado!$B$2:$B439, "=Chiapas") -> 2645 | D11: =SUMIFS(Concentrado!E$2:E439,Concentrado!$A$2:$A439,"="&$A11,Concentrado!$B$2:$B439, "=Chiapas") -> 1727 | E11: =SUMIFS(Concentrado!F$2:F439,Concentrado!$A$2:$A439,"="&$A11,Concentrado!$B$2:$B439, "=Chiapas") -> 145 | F11: =SUMIFS(Concentrado!G$2:G439,Concentrado!$A$2:$A439,"="&$A11,Concentrado!$B$2:$B439, "=Chiapas") -> 104
A12: 2022 | B12: =SUMIFS(Concentrado!C$2:C440,Concentrado!$A$2:$A440,"="&$A12,Concentrado!$B$2:$B440, "=Chiapas") -> 3928 | C12: =SUMIFS(Concentrado!D$2:D440,Concentrado!$A$2:$A440,"="&$A12,Concentrado!$B$2:$B440, "=Chiapas") -> 2699 | D12: =SUMIFS(Concentrado!E$2:E440,Concentrado!$A$2:$A440,"="&$A12,Concentrado!$B$2:$B440, "=Chiapas") -> 1773 | E12: =SUMIFS(Concentrado!F$2:F440,Concentrado!$A$2:$A440,"="&$A12,Concentrado!$B$2:$B440, "=Chiapas") -> 151 | F12: =SUMIFS(Concentrado!G$2:G440,Concentrado!$A$2:$A440,"="&$A12,Concentrado!$B$2:$B440, "=Chiapas") -> 114
A13: 2023 | B13: =SUMIFS(Concentrado!C$2:C441,Concentrado!$A$2:$A441,"="&$A13,Concentrado!$B$2:$B441, "=Chiapas") -> 3851 | C13: =SUMIFS(Concentrado!D$2:D441,Concentrado!$A$2:$A441,"="&$A13,Concentrado!$B$2:$B441, "=Chiapas") -> 2503 | D13: =SUMIFS(Concentrado!E$2:E441,Concentrado!$A$2:$A441,"="&$A13,Concentrado!$B$2:$B441, "=Chiapas") -> 1735 | E13: =SUMIFS(Concentrado!F$2:F441,Concentrado!$A$2:$A441,"="&$A13,Concentrado!$B$2:$B441, "=Chiapas") -> 144 | F13: =SUMIFS(Concentrado!G$2:G441,Concentrado!$A$2:$A441,"="&$A13,Concentrado!$B$2:$B441, "=Chiapas") -> 119
A14: 2024 | B14: =SUMIFS(Concentrado!C$2:C442,Concentrado!$A$2:$A442,"="&$A14,Concentrado!$B$2:$B442, "=Chiapas") -> 3953 | C14: =SUMIFS(Concentrado!D$2:D442,Concentrado!$A$2:$A442,"="&$A14,Concentrado!$B$2:$B442, "=Chiapas") -> 2427 | D14: =SUMIFS(Concentrado!E$2:E442,Concentrado!$A$2:$A442,"="&$A14,Concentrado!$B$2:$B442, "=Chiapas") -> 1914 | E14: =SUMIFS(Concentrado!F$2:F442,Concentrado!$A$2:$A442,"="&$A14,Concentrado!$B$2:$B442, "=Chiapas") -> 152 | F14: =SUMIFS(Concentrado!G$2:G442,Concentrado!$A$2:$A442,"="&$A14,Concentrado!$B$2:$B442, "=Chiapas") -> 129

Sheet CHI
A1: Año | B1: Consultorios | C1: Camas hospitalarias | D1: Camas no hospitalarias | E1: Quirófanos | F1: Salas expulsión
A2: 2012 | B2: =SUMIFS(Concentrado!C$2:C430,Concentrado!$A$2:$A430,"="&$A2,Concentrado!$B$2:$B430, "=Chihuahua") -> 1892 | C2: =SUMIFS(Concentrado!D$2:D430,Concentrado!$A$2:$A430,"="&$A2,Concentrado!$B$2:$B430, "=Chihuahua") -> 2767 | D2: =SUMIFS(Concentrado!E$2:E430,Concentrado!$A$2:$A430,"="&$A2,Concentrado!$B$2:$B430, "=Chihuahua") -> 1682 | E2: =SUMIFS(Concentrado!F$2:F430,Concentrado!$A$2:$A430,"="&$A2,Concentrado!$B$2:$B430, "=Chihuahua") -> 113 | F2: =SUMIFS(Concentrado!G$2:G430,Concentrado!$A$2:$A430,"="&$A2,Concentrado!$B$2:$B430, "=Chihuahua") -> 75
A3: 2013 | B3: =SUMIFS(Concentrado!C$2:C431,Concentrado!$A$2:$A431,"="&$A3,Concentrado!$B$2:$B431, "=Chihuahua") -> 2012 | C3: =SUMIFS(Concentrado!D$2:D431,Concentrado!$A$2:$A431,"="&$A3,Concentrado!$B$2:$B431, "=Chihuahua") -> 2781 | D3: =SUMIFS(Concentrado!E$2:E431,Concentrado!$A$2:$A431,"="&$A3,Concentrado!$B$2:$B431, "=Chihuahua") -> 1801 | E3: =SUMIFS(Concentrado!F$2:F431,Concentrado!$A$2:$A431,"="&$A3,Concentrado!$B$2:$B431, "=Chihuahua") -> 122 | F3: =SUMIFS(Concentrado!G$2:G431,Concentrado!$A$2:$A431,"="&$A3,Concentrado!$B$2:$B431, "=Chihuahua") -> 75
A4: 2014 | B4: =SUMIFS(Concentrado!C$2:C432,Concentrado!$A$2:$A432,"="&$A4,Concentrado!$B$2:$B432, "=Chihuahua") -> 2042 | C4: =SUMIFS(Concentrado!D$2:D432,Concentrado!$A$2:$A432,"="&$A4,Concentrado!$B$2:$B432, "=Chihuahua") -> 2800 | D4: =SUMIFS(Concentrado!E$2:E432,Concentrado!$A$2:$A432,"="&$A4,Concentrado!$B$2:$B432, "=Chihuahua") -> 1748 | E4: =SUMIFS(Concentrado!F$2:F432,Concentrado!$A$2:$A432,"="&$A4,Concentrado!$B$2:$B432, "=Chihuahua") -> 113 | F4: =SUMIFS(Concentrado!G$2:G432,Concentrado!$A$2:$A432,"="&$A4,Concentrado!$B$2:$B432, "=Chihuahua") -> 74
A5: 2015 | B5: =SUMIFS(Concentrado!C$2:C433,Concentrado!$A$2:$A433,"="&$A5,Concentrado!$B$2:$B433, "=Chihuahua") -> 2080 | C5: =SUMIFS(Concentrado!D$2:D433,Concentrado!$A$2:$A433,"="&$A5,Concentrado!$B$2:$B433, "=Chihuahua") -> 2873 | D5: =SUMIFS(Concentrado!E$2:E433,Concentrado!$A$2:$A433,"="&$A5,Concentrado!$B$2:$B433, "=Chihuahua") -> 1637 | E5: =SUMIFS(Concentrado!F$2:F433,Concentrado!$A$2:$A433,"="&$A5,Concentrado!$B$2:$B433, "=Chihuahua") -> 121 | F5: =SUMIFS(Concentrado!G$2:G433,Concentrado!$A$2:$A433,"="&$A5,Concentrado!$B$2:$B433, "=Chihuahua") -> 89
A6: 2016 | B6: =SUMIFS(Concentrado!C$2:C434,Concentrado!$A$2:$A434,"="&$A6,Concentrado!$B$2:$B434, "=Chihuahua") -> 2029 | C6: =SUMIFS(Concentrado!D$2:D434,Concentrado!$A$2:$A434,"="&$A6,Concentrado!$B$2:$B434, "=Chihuahua") -> 2814 | D6: =SUMIFS(Concentrado!E$2:E434,Concentrado!$A$2:$A434,"="&$A6,Concentrado!$B$2:$B434, "=Chihuahua") -> 1685 | E6: =SUMIFS(Concentrado!F$2:F434,Concentrado!$A$2:$A434,"="&$A6,Concentrado!$B$2:$B434, "=Chihuahua") -> 120 | F6: =SUMIFS(Concentrado!G$2:G434,Concentrado!$A$2:$A434,"="&$A6,Concentrado!$B$2:$B434, "=Chihuahua") -> 95
A7: 2017 | B7: =SUMIFS(Concentrado!C$2:C435,Concentrado!$A$2:$A435,"="&$A7,Concentrado!$B$2:$B435, "=Chihuahua") -> 2003 | C7: =SUMIFS(Concentrado!D$2:D435,Concentrado!$A$2:$A435,"="&$A7,Concentrado!$B$2:$B435, "=Chihuahua") -> 2905 | D7: =SUMIFS(Concentrado!E$2:E435,Concentrado!$A$2:$A435,"="&$A7,Concentrado!$B$2:$B435, "=Chihuahua") -> 1620 | E7: =SUMIFS(Concentrado!F$2:F435,Concentrado!$A$2:$A435,"="&$A7,Concentrado!$B$2:$B435, "=Chihuahua") -> 133 | F7: =SUMIFS(Concentrado!G$2:G435,Concentrado!$A$2:$A435,"="&$A7,Concentrado!$B$2:$B435, "=Chihuahua") -> 97
A8: 2018 | B8: =SUMIFS(Concentrado!C$2:C436,Concentrado!$A$2:$A436,"="&$A8,Concentrado!$B$2:$B436, "=Chihuahua") -> 2148 | C8: =SUMIFS(Concentrado!D$2:D436,Concentrado!$A$2:$A436,"="&$A8,Concentrado!$B$2:$B436, "=Chihuahua") -> 2915 | D8: =SUMIFS(Concentrado!E$2:E436,Concentrado!$A$2:$A436,"="&$A8,Concentrado!$B$2:$B436, "=Chihuahua") -> 1619 | E8: =SUMIFS(Concentrado!F$2:F436,Concentrado!$A$2:$A436,"="&$A8,Concentrado!$B$2:$B436, "=Chihuahua") -> 141 | F8: =SUMIFS(Concentrado!G$2:G436,Concentrado!$A$2:$A436,"="&$A8,Concentrado!$B$2:$B436, "=Chihuahua") -> 97
A9: 2019 | B9: =SUMIFS(Concentrado!C$2:C437,Concentrado!$A$2:$A437,"="&$A9,Concentrado!$B$2:$B437, "=Chihuahua") -> 2079 | C9: =SUMIFS(Concentrado!D$2:D437,Concentrado!$A$2:$A437,"="&$A9,Concentrado!$B$2:$B437, "=Chihuahua") -> 3015 | D9: =SUMIFS(Concentrado!E$2:E437,Concentrado!$A$2:$A437,"="&$A9,Concentrado!$B$2:$B437, "=Chihuahua") -> 1731 | E9: =SUMIFS(Concentrado!F$2:F437,Concentrado!$A$2:$A437,"="&$A9,Concentrado!$B$2:$B437, "=Chihuahua") -> 138 | F9: =SUMIFS(Concentrado!G$2:G437,Concentrado!$A$2:$A437,"="&$A9,Concentrado!$B$2:$B437, "=Chihuahua") -> 114
A10: 2020 | B10: =SUMIFS(Concentrado!C$2:C438,Concentrado!$A$2:$A438,"="&$A10,Concentrado!$B$2:$B438, "=Chihuahua") -> 2267 | C10: =SUMIFS(Concentrado!D$2:D438,Concentrado!$A$2:$A438,"="&$A10,Concentrado!$B$2:$B438, "=Chihuahua") -> 2845 | D10: =SUMIFS(Concentrado!E$2:E438,Concentrado!$A$2:$A438,"="&$A10,Concentrado!$B$2:$B438, "=Chihuahua") -> 1758 | E10: =SUMIFS(Concentrado!F$2:F438,Concentrado!$A$2:$A438,"="&$A10,Concentrado!$B$2:$B438, "=Chihuahua") -> 133 | F10: =SUMIFS(Concentrado!G$2:G438,Concentrado!$A$2:$A438,"="&$A10,Concentrado!$B$2:$B438, "=Chihuahua") -> 93
A11: 2021 | B11: =SUMIFS(Concentrado!C$2:C439,Concentrado!$A$2:$A439,"="&$A11,Concentrado!$B$2:$B439, "=Chihuahua") -> 2120 | C11: =SUMIFS(Concentrado!D$2:D439,Concentrado!$A$2:$A439,"="&$A11,Concentrado!$B$2:$B439, "=Chihuahua") -> 2906 | D11: =SUMIFS(Concentrado!E$2:E439,Concentrado!$A$2:$A439,"="&$A11,Concentrado!$B$2:$B439, "=Chihuahua") -> 1758 | E11: =SUMIFS(Concentrado!F$2:F439,Concentrado!$A$2:$A439,"="&$A11,Concentrado!$B$2:$B439, "=Chihuahua") -> 122 | F11: =SUMIFS(Concentrado!G$2:G439,Concentrado!$A$2:$A439,"="&$A11,Concentrado!$B$2:$B439, "=Chihuahua") -> 93
A12: 2022 | B12: =SUMIFS(Concentrado!C$2:C440,Concentrado!$A$2:$A440,"="&$A12,Concentrado!$B$2:$B440, "=Chihuahua") -> 2269 | C12: =SUMIFS(Concentrado!D$2:D440,Concentrado!$A$2:$A440,"="&$A12,Concentrado!$B$2:$B440, "=Chihuahua") -> 3131 | D12: =SUMIFS(Concentrado!E$2:E440,Concentrado!$A$2:$A440,"="&$A12,Concentrado!$B$2:$B440, "=Chihuahua") -> 1569 | E12: =SUMIFS(Concentrado!F$2:F440,Concentrado!$A$2:$A440,"="&$A12,Concentrado!$B$2:$B440, "=Chihuahua") -> 125 | F12: =SUMIFS(Concentrado!G$2:G440,Concentrado!$A$2:$A440,"="&$A12,Concentrado!$B$2:$B440, "=Chihuahua") -> 94
A13: 2023 | B13: =SUMIFS(Concentrado!C$2:C441,Concentrado!$A$2:$A441,"="&$A13,Concentrado!$B$2:$B441, "=Chihuahua") -> 2302 | C13: =SUMIFS(Concentrado!D$2:D441,Concentrado!$A$2:$A441,"="&$A13,Concentrado!$B$2:$B441, "=Chihuahua") -> 3007 | D13: =SUMIFS(Concentrado!E$2:E441,Concentrado!$A$2:$A441,"="&$A13,Concentrado!$B$2:$B441, "=Chihuahua") -> 1587 | E13: =SUMIFS(Concentrado!F$2:F441,Concentrado!$A$2:$A441,"="&$A13,Concentrado!$B$2:$B441, "=Chihuahua") -> 124 | F13: =SUMIFS(Concentrado!G$2:G441,Concentrado!$A$2:$A441,"="&$A13,Concentrado!$B$2:$B441, "=Chihuahua") -> 74
A14: 2024 | B14: =SUMIFS(Concentrado!C$2:C442,Concentrado!$A$2:$A442,"="&$A14,Concentrado!$B$2:$B442, "=Chihuahua") -> 2343 | C14: =SUMIFS(Concentrado!D$2:D442,Concentrado!$A$2:$A442,"="&$A14,Concentrado!$B$2:$B442, "=Chihuahua") -> 3223 | D14: =SUMIFS(Concentrado!E$2:E442,Concentrado!$A$2:$A442,"="&$A14,Concentrado!$B$2:$B442, "=Chihuahua") -> 1612 | E14: =SUMIFS(Concentrado!F$2:F442,Concentrado!$A$2:$A442,"="&$A14,Concentrado!$B$2:$B442, "=Chihuahua") -> 144 | F14: =SUMIFS(Concentrado!G$2:G442,Concentrado!$A$2:$A442,"="&$A14,Concentrado!$B$2:$B442, "=Chihuahua") -> 70

Sheet CDMX
A1: Año | B1: Consultorios | C1: Camas hospitalarias | D1: Camas no hospitalarias | E1: Quirófanos | F1: Salas expulsión
A2: 2012 | B2: =SUMIFS(Concentrado!C$2:C430,Concentrado!$A$2:$A430,"="&$A2,Concentrado!$B$2:$B430, "=CDMX") -> 8377 | C2: =SUMIFS(Concentrado!D$2:D430,Concentrado!$A$2:$A430,"="&$A2,Concentrado!$B$2:$B430, "=CDMX") -> 16107 | D2: =SUMIFS(Concentrado!E$2:E430,Concentrado!$A$2:$A430,"="&$A2,Concentrado!$B$2:$B430, "=CDMX") -> 6287 | E2: =SUMIFS(Concentrado!F$2:F430,Concentrado!$A$2:$A430,"="&$A2,Concentrado!$B$2:$B430, "=CDMX") -> 644 | F2: =SUMIFS(Concentrado!G$2:G430,Concentrado!$A$2:$A430,"="&$A2,Concentrado!$B$2:$B430, "=CDMX") -> 111
A3: 2013 | B3: =SUMIFS(Concentrado!C$2:C431,Concentrado!$A$2:$A431,"="&$A3,Concentrado!$B$2:$B431, "=CDMX") -> 8629 | C3: =SUMIFS(Concentrado!D$2:D431,Concentrado!$A$2:$A431,"="&$A3,Concentrado!$B$2:$B431, "=CDMX") -> 15787 | D3: =SUMIFS(Concentrado!E$2:E431,Concentrado!$A$2:$A431,"="&$A3,Concentrado!$B$2:$B431, "=CDMX") -> 6960 | E3: =SUMIFS(Concentrado!F$2:F431,Concentrado!$A$2:$A431,"="&$A3,Concentrado!$B$2:$B431, "=CDMX") -> 663 | F3: =SUMIFS(Concentrado!G$2:G431,Concentrado!$A$2:$A431,"="&$A3,Concentrado!$B$2:$B431, "=CDMX") -> 111
A4: 2014 | B4: =SUMIFS(Concentrado!C$2:C432,Concentrado!$A$2:$A432,"="&$A4,Concentrado!$B$2:$B432, "=CDMX") -> 8957 | C4: =SUMIFS(Concentrado!D$2:D432,Concentrado!$A$2:$A432,"="&$A4,Concentrado!$B$2:$B432, "=CDMX") -> 16259 | D4: =SUMIFS(Concentrado!E$2:E432,Concentrado!$A$2:$A432,"="&$A4,Concentrado!$B$2:$B432, "=CDMX") -> 6463 | E4: =SUMIFS(Concentrado!F$2:F432,Concentrado!$A$2:$A432,"="&$A4,Concentrado!$B$2:$B432, "=CDMX") -> 633 | F4: =SUMIFS(Concentrado!G$2:G432,Concentrado!$A$2:$A432,"="&$A4,Concentrado!$B$2:$B432, "=CDMX") -> 108
A5: 2015 | B5: =SUMIFS(Concentrado!C$2:C433,Concentrado!$A$2:$A433,"="&$A5,Concentrado!$B$2:$B433, "=CDMX") -> 9173 | C5: =SUMIFS(Concentrado!D$2:D433,Concentrado!$A$2:$A433,"="&$A5,Concentrado!$B$2:$B433, "=CDMX") -> 15798 | D5: =SUMIFS(Concentrado!E$2:E433,Concentrado!$A$2:$A433,"="&$A5,Concentrado!$B$2:$B433, "=CDMX") -> 5795 | E5: =SUMIFS(Concentrado!F$2:F433,Concentrado!$A$2:$A433,"="&$A5,Concentrado!$B$2:$B433, "=CDMX") -> 642 | F5: =SUMIFS(Concentrado!G$2:G433,Concentrado!$A$2:$A433,"="&$A5,Concentrado!$B$2:$B433, "=CDMX") -> 109
A6: 2016 | B6: =SUMIFS(Concentrado!C$2:C434,Concentrado!$A$2:$A434,"="&$A6,Concentrado!$B$2:$B434, "=CDMX") -> 9194 | C6: =SUMIFS(Concentrado!D$2:D434,Concentrado!$A$2:$A434,"="&$A6,Concentrado!$B$2:$B434, "=CDMX") -> 15627 | D6: =SUMIFS(Concentrado!E$2:E434,Concentrado!$A$2:$A434,"="&$A6,Concentrado!$B$2:$B434, "=CDMX") -> 5364 | E6: =SUMIFS(Concentrado!F$2:F434,Concentrado!$A$2:$A434,"="&$A6,Concentrado!$B$2:$B434, "=CDMX") -> 652 | F6: =SUMIFS(Concentrado!G$2:G434,Concentrado!$A$2:$A434,"="&$A6,Concentrado!$B$2:$B434, "=CDMX") -> 109
A7: 2017 | B7: =SUMIFS(Concentrado!C$2:C435,Concentrado!$A$2:$A435,"="&$A7,Concentrado!$B$2:$B435, "=CDMX") -> 9031 | C7: =SUMIFS(Concentrado!D$2:D435,Concentrado!$A$2:$A435,"="&$A7,Concentrado!$B$2:$B435, "=CDMX") -> 15457 | D7: =SUMIFS(Concentrado!E$2:E435,Concentrado!$A$2:$A435,"="&$A7,Concentrado!$B$2:$B435, "=CDMX") -> 5304 | E7: =SUMIFS(Concentrado!F$2:F435,Concentrado!$A$2:$A435,"="&$A7,Concentrado!$B$2:$B435, "=CDMX") -> 648 | F7: =SUMIFS(Concentrado!G$2:G435,Concentrado!$A$2:$A435,"="&$A7,Concentrado!$B$2:$B435, "=CDMX") -> 102
A8: 2018 | B8: =SUMIFS(Concentrado!C$2:C436,Concentrado!$A$2:$A436,"="&$A8,Concentrado!$B$2:$B436, "=CDMX") -> 9222 | C8: =SUMIFS(Concentrado!D$2:D436,Concentrado!$A$2:$A436,"="&$A8,Concentrado!$B$2:$B436, "=CDMX") -> 15632 | D8: =SUMIFS(Concentrado!E$2:E436,Concentrado!$A$2:$A436,"="&$A8,Concentrado!$B$2:$B436, "=CDMX") -> 5125 | E8: =SUMIFS(Concentrado!F$2:F436,Concentrado!$A$2:$A436,"="&$A8,Concentrado!$B$2:$B436, "=CDMX") -> 650 | F8: =SUMIFS(Concentrado!G$2:G436,Concentrado!$A$2:$A436,"="&$A8,Concentrado!$B$2:$B436, "=CDMX") -> 102
A9: 2019 | B9: =SUMIFS(Concentrado!C$2:C437,Concentrado!$A$2:$A437,"="&$A9,Concentrado!$B$2:$B437, "=CDMX") -> 9092 | C9: =SUMIFS(Concentrado!D$2:D437,Concentrado!$A$2:$A437,"="&$A9,Concentrado!$B$2:$B437, "=CDMX") -> 15542 | D9: =SUMIFS(Concentrado!E$2:E437,Concentrado!$A$2:$A437,"="&$A9,Concentrado!$B$2:$B437, "=CDMX") -> 5241 | E9: =SUMIFS(Concentrado!F$2:F437,Concentrado!$A$2:$A437,"="&$A9,Concentrado!$B$2:$B437, "=CDMX") -> 647 | F9: =SUMIFS(Concentrado!G$2:G437,Concentrado!$A$2:$A437,"="&$A9,Concentrado!$B$2:$B437, "=CDMX") -> 100
